<?xml version="1.0"?>
<robot name="hug">
  <link name="base_hug">
    <visual>
      <origin rpy="0 0 0" xyz="0 0 0"/>
      <geometry>
        <mesh filename="package://cola2_sim/data/robot/hug/hug.osg" />
      </geometry>
    </visual>
  </link>
  
  <link name="seaking_profiler">
    <visual>
      <origin rpy="0.0 0.0 0.0" xyz="0 0 0"/>
      <geometry>
        <cylinder radius="0.05" length="0.1"/>
      </geometry>
    </visual>
  </link>
  
  <joint name="robot2profiler" type="continuous">
    <parent link="base_hug"/>
    <child link="seaking_profiler"/>
    <axis xyz="0 0 1"/>
    <origin rpy="-1.57 3.14 0.0" xyz="0.7 -0.15 0.0"/>
  </joint>
</robot>
